<?xml version='1.0' encoding='utf-8'?>
<robot name="mtm">
  <joint name="${prefix}fixed_joint" type="fixed">
    <parent link="${parent_link}" />
    <child link="${prefix}top_panel" />
    <origin rpy="${rpy}" xyz="${xyz}" />
  </joint>
  <link name="${prefix}top_panel">
    <visual>
      <geometry>
        <mesh filename="Top Panel.dae" />
      </geometry>
    </visual>
    <collision>
      <geometry>
        <mesh filename="Top Panel.STL" />
      </geometry>
    </collision>
    <inertial>
      <origin xyz="0 0 0" rpy="0 0 0" />
      <mass value=".9" />
      <inertia ixx="9.0" ixy="0.0" ixz="0.0" iyy="9.0" iyz="0.0" izz="9.0" />
    </inertial>
  </link>
  <joint name="${prefix}outer_yaw_joint" type="revolute">
    <parent link="${prefix}top_panel" />
    <child link="${prefix}outer_yaw_link" />
    <origin rpy="0 0 ${PI/2}" xyz="0 0 0" />
    <axis xyz="0 0 1" />
    <limit effort="50.0" lower="${-75/180*PI}" upper="${PI/4}" velocity="2" />
    <joint_properties damping="1.0" friction="0.0" />
  </joint>
  <link name="${prefix}outer_yaw_link">
    <visual>
      <geometry>
        <mesh filename="OutPitch_Shoulder.dae" />
      </geometry>
    </visual>
    <collision>
      <geometry>
        <mesh filename="OutPitch_Shoulder.STL" />
      </geometry>
    </collision>
    <inertial>
      <mass value="1" />
      <inertia ixx="10.0" ixy="0.0" ixz="0.0" iyy="10.0" iyz="0.0" izz="10.0" />
    </inertial>
  </link>
  <link name="${prefix}back_parallel_link">
    <visual>
      <geometry>
        <mesh filename="ArmParallel.dae" />
      </geometry>
    </visual>
    <collision>
      <geometry>
        <mesh filename="ArmParallel.STL" />
      </geometry>
    </collision>
    <inertial>
      <mass value=".9" />
      <inertia ixx="9.0" ixy="0.0" ixz="0.0" iyy="9.0" iyz="0.0" izz="9.0" />
    </inertial>
  </link>
  <link name="${prefix}top_parallel_link">
    <visual>
      <geometry>
        <mesh filename="ArmParallel1.dae" />
      </geometry>
    </visual>
    <collision>
      <geometry>
        <mesh filename="ArmParallel1.STL" />
      </geometry>
    </collision>
    <inertial>
      <mass value=".5" />
      <inertia ixx="5.0" ixy="0.0" ixz="0.0" iyy="5.0" iyz="0.0" izz="5.0" />
    </inertial>
  </link>
  <joint name="${prefix}shoulder_pitch_joint" type="revolute">
    <parent link="${prefix}outer_yaw_link" />
    <child link="${prefix}back_parallel_link" />
    <origin rpy="${-PI/2} ${-PI/2} 0" xyz="0 0 -0.19037" />
    <axis xyz="0 0 1" />
    <limit effort="100.0" lower="${-PI/4}" upper="${PI/4}" velocity="10" />
    <joint_properties damping="1.0" friction="0.0" />
  </joint>
  <joint name="${prefix}shoulder_pitch_parallel_joint" type="revolute">
    <parent link="${prefix}back_parallel_link" />
    <child link="${prefix}top_parallel_link" />
    <origin rpy="0 0 ${-PI/2}" xyz="0 0 0.065" />
    <axis xyz="0 0 1" />
    <limit effort="100.0" lower="${-PI/2}" upper="${PI/2}" velocity="10" />
    <joint_properties damping="1.0" friction="0.0" />
    <mimic joint="${prefix}elbow_pitch_joint" multiplier="1" />
  </joint>
  <joint name="${prefix}elbow_pitch_joint" type="revolute">
    <parent link="${prefix}back_parallel_link" />
    <child link="${prefix}bottom_parallel_link" />
    <origin rpy="0 0 ${PI/2}" xyz="-.2794 0 0" />
    <axis xyz="0 0 1" />
    <limit effort="100.0" lower="${-PI/4}" upper="${PI/4}" velocity="10" />
    <joint_properties damping="1.0" friction="0.0" />
  </joint>
  <joint name="${prefix}wrist_platform_joint" type="revolute">
    <parent link="${prefix}bottom_parallel_link" />
    <child link="${prefix}wrist_platform_link" />
    <origin rpy="${PI/2} 0 0" xyz="-0.3645 -0.156 0.0" />
    <axis xyz="0 0 1" />
    <limit effort="100.0" lower="${-60/180*PI}" upper="${245/180*PI}" velocity="10" />
    <joint_properties damping="1.0" friction="0.0" />
  </joint>
  <link name="${prefix}wrist_platform_link">
    <visual>
      <geometry>
        <mesh filename="WristPlatform.dae" />
      </geometry>
    </visual>
    <collision>
      <geometry>
        <mesh filename="WristPlatform.STL" />
      </geometry>
    </collision>
    <inertial>
      <mass value="0.4" />
      <inertia ixx="0.1" ixy="0.0" ixz="0.0" iyy="0.1" iyz="0.0" izz="0.1" />
    </inertial>
  </link>
  <link name="${prefix}bottom_parallel_link">
    <visual>
      <geometry>
        <mesh filename="BottomArm.dae" />
      </geometry>
    </visual>
    <collision>
      <geometry>
        <mesh filename="BottomArm.STL" />
      </geometry>
    </collision>
    <inertial>
      <mass value="0.8" />
      <inertia ixx="0.1" ixy="0.0" ixz="0.0" iyy="0.1" iyz="0.0" izz="0.1" />
    </inertial>
  </link>
  <joint name="${prefix}wrist_pitch_joint" type="revolute">
    <parent link="${prefix}wrist_platform_link" />
    <child link="${prefix}wrist_pitch_link" />
    <origin rpy="${-PI/2} 0 0" xyz="0 0 0" />
    <axis xyz="0 0 1" />
    <limit effort="100.0" lower="${-PI/2}" upper="${PI}" velocity="10" />
    <joint_properties damping="1.0" friction="0.0" />
  </joint>
  <link name="${prefix}wrist_pitch_link">
    <visual>
      <geometry>
        <mesh filename="WristPitch.dae" />
      </geometry>
    </visual>
    <collision>
      <geometry>
        <mesh filename="WristPitch.STL" />
      </geometry>
    </collision>
    <inertial>
      <mass value="0.2" />
      <inertia ixx="0.1" ixy="0.0" ixz="0.0" iyy="0.1" iyz="0.0" izz="0.1" />
    </inertial>
  </link>
  <joint name="${prefix}wrist_yaw_joint" type="revolute">
    <parent link="${prefix}wrist_pitch_link" />
    <child link="${prefix}wrist_yaw_link" />
    <origin rpy="${PI/2} ${-PI/2} 0" xyz="0 0 0" />
    <axis xyz="0 0 1" />
    <limit effort="100.0" lower="${-PI/4}" upper="${PI/4}" velocity="10" />
    <joint_properties damping="1.0" friction="0.0" />
  </joint>
  <link name="${prefix}wrist_yaw_link">
    <visual>
      <geometry>
        <mesh filename="WristYaw.dae" />
      </geometry>
    </visual>
    <collision>
      <geometry>
        <mesh filename="WristYaw.STL" />
      </geometry>
    </collision>
    <inertial>
      <mass value="0.2" />
      <inertia ixx="0.1" ixy="0.0" ixz="0.0" iyy="0.1" iyz="0.0" izz="0.1" />
    </inertial>
  </link>
  <joint name="${prefix}wrist_roll_joint" type="revolute">
    <parent link="${prefix}wrist_yaw_link" />
    <child link="${prefix}wrist_roll_link" />
    <origin rpy="${-PI/2} ${PI/2} 0" xyz="0 -.039 0" />
    <axis xyz="0 0 -1" />
    <limit effort="100.0" lower="${-1.5*PI}" upper="${1.5*PI}" velocity="10" />
    <joint_properties damping="1.0" friction="0.0" />
  </joint>
  <link name="${prefix}wrist_roll_link">
    <visual>
      <geometry>
        <mesh filename="WristRoll.dae" />
      </geometry>
    </visual>
    <collision>
      <geometry>
        <mesh filename="WristRoll.STL" />
      </geometry>
    </collision>
    <inertial>
      <mass value="0.1" />
      <inertia ixx="0.1" ixy="0.0" ixz="0.0" iyy="0.1" iyz="0.0" izz="0.1" />
    </inertial>
  </link>
  <joint name="${prefix}base" type="fixed">
    <parent link="${prefix}top_panel" />
    <child link="${prefix}base" />
    <origin rpy="0 0 0" xyz="0 0 -0.190" />
  </joint>
  <link name="${prefix}base" />
  <joint name="${prefix}end_effector" type="fixed">
    <parent link="${prefix}wrist_roll_link" />
    <child link="${prefix}ee_link" />
    <origin rpy="0 ${PI} 0" xyz="0 0 0.039" />
  </joint>
  <link name="${prefix}ee_link" />
</robot>