<?xml version='1.0' encoding='utf-8'?>
<robot name="mtm">
  <link name="world" />
  <joint name="fixed_joint" type="fixed">
    <parent link="world" />
    <child link="top_panel" />
    <origin rpy="0 0 0" xyz="0 0 0" />
  </joint>
  <link name="top_panel">
    <visual>
      <geometry>
        <mesh filename="Top Panel.dae" />
      </geometry>
    </visual>
    <collision>
      <geometry>
        <mesh filename="Top Panel.STL" />
      </geometry>
    </collision>
    <inertial>
      <origin xyz="0 0 0" rpy="0 0 0" />
      <mass value=".9" />
      <inertia ixx="9.0" ixy="0.0" ixz="0.0" iyy="9.0" iyz="0.0" izz="9.0" />
    </inertial>
  </link>
  <joint name="outer_yaw_joint" type="revolute">
    <parent link="top_panel" />
    <child link="outer_yaw_link" />
    <origin rpy="0 0 1.57079632679" xyz="0 0 0" />
    <axis xyz="0 0 1" />
    <limit effort="50.0" lower="-1.308996939" upper="0.785398163397" velocity="2" />
    <joint_properties damping="1.0" friction="0.0" />
  </joint>
  <link name="outer_yaw_link">
    <visual>
      <geometry>
        <mesh filename="OutPitch_Shoulder.dae" />
      </geometry>
    </visual>
    <collision>
      <geometry>
        <mesh filename="OutPitch_Shoulder.STL" />
      </geometry>
    </collision>
    <inertial>
      <mass value="1" />
      <inertia ixx="10.0" ixy="0.0" ixz="0.0" iyy="10.0" iyz="0.0" izz="10.0" />
    </inertial>
  </link>
  <link name="back_parallel_link">
    <visual>
      <geometry>
        <mesh filename="ArmParallel.dae" />
      </geometry>
    </visual>
    <collision>
      <geometry>
        <mesh filename="ArmParallel.STL" />
      </geometry>
    </collision>
    <inertial>
      <mass value=".9" />
      <inertia ixx="9.0" ixy="0.0" ixz="0.0" iyy="9.0" iyz="0.0" izz="9.0" />
    </inertial>
  </link>
  <link name="top_parallel_link">
    <visual>
      <geometry>
        <mesh filename="ArmParallel1.dae" />
      </geometry>
    </visual>
    <collision>
      <geometry>
        <mesh filename="ArmParallel1.STL" />
      </geometry>
    </collision>
    <inertial>
      <mass value=".5" />
      <inertia ixx="5.0" ixy="0.0" ixz="0.0" iyy="5.0" iyz="0.0" izz="5.0" />
    </inertial>
  </link>
  <joint name="shoulder_pitch_joint" type="revolute">
    <parent link="outer_yaw_link" />
    <child link="back_parallel_link" />
    <origin rpy="-1.57079632679 -1.57079632679 0" xyz="0 0 -0.19037" />
    <axis xyz="0 0 1" />
    <limit effort="100.0" lower="-0.785398163397" upper="0.785398163397" velocity="10" />
    <joint_properties damping="1.0" friction="0.0" />
  </joint>
  <joint name="shoulder_pitch_parallel_joint" type="revolute">
    <parent link="back_parallel_link" />
    <child link="top_parallel_link" />
    <origin rpy="0 0 -1.57079632679" xyz="0 0 0.065" />
    <axis xyz="0 0 1" />
    <limit effort="100.0" lower="-1.57079632679" upper="1.57079632679" velocity="10" />
    <joint_properties damping="1.0" friction="0.0" />
    <mimic joint="elbow_pitch_joint" multiplier="1" />
  </joint>
  <joint name="elbow_pitch_joint" type="revolute">
    <parent link="back_parallel_link" />
    <child link="bottom_parallel_link" />
    <origin rpy="0 0 1.57079632679" xyz="-.2794 0 0" />
    <axis xyz="0 0 1" />
    <limit effort="100.0" lower="-0.785398163397" upper="0.785398163397" velocity="10" />
    <joint_properties damping="1.0" friction="0.0" />
  </joint>
  <joint name="wrist_platform_joint" type="revolute">
    <parent link="bottom_parallel_link" />
    <child link="wrist_platform_link" />
    <origin rpy="1.57079632679 0 0" xyz="-0.3645 -0.156 0.0" />
    <axis xyz="0 0 1" />
    <limit effort="100.0" lower="-1.0471975512" upper="4.27605666739" velocity="10" />
    <joint_properties damping="1.0" friction="0.0" />
  </joint>
  <link name="wrist_platform_link">
    <visual>
      <geometry>
        <mesh filename="WristPlatform.dae" />
      </geometry>
    </visual>
    <collision>
      <geometry>
        <mesh filename="WristPlatform.STL" />
      </geometry>
    </collision>
    <inertial>
      <mass value="0.4" />
      <inertia ixx="0.1" ixy="0.0" ixz="0.0" iyy="0.1" iyz="0.0" izz="0.1" />
    </inertial>
  </link>
  <link name="bottom_parallel_link">
    <visual>
      <geometry>
        <mesh filename="BottomArm.dae" />
      </geometry>
    </visual>
    <collision>
      <geometry>
        <mesh filename="BottomArm.STL" />
      </geometry>
    </collision>
    <inertial>
      <mass value="0.8" />
      <inertia ixx="0.1" ixy="0.0" ixz="0.0" iyy="0.1" iyz="0.0" izz="0.1" />
    </inertial>
  </link>
  <joint name="wrist_pitch_joint" type="revolute">
    <parent link="wrist_platform_link" />
    <child link="wrist_pitch_link" />
    <origin rpy="-1.57079632679 0 0" xyz="0 0 0" />
    <axis xyz="0 0 1" />
    <limit effort="100.0" lower="-1.57079632679" upper="3.14159265359" velocity="10" />
    <joint_properties damping="1.0" friction="0.0" />
  </joint>
  <link name="wrist_pitch_link">
    <visual>
      <geometry>
        <mesh filename="WristPitch.dae" />
      </geometry>
    </visual>
    <collision>
      <geometry>
        <mesh filename="WristPitch.STL" />
      </geometry>
    </collision>
    <inertial>
      <mass value="0.2" />
      <inertia ixx="0.1" ixy="0.0" ixz="0.0" iyy="0.1" iyz="0.0" izz="0.1" />
    </inertial>
  </link>
  <joint name="wrist_yaw_joint" type="revolute">
    <parent link="wrist_pitch_link" />
    <child link="wrist_yaw_link" />
    <origin rpy="1.57079632679 -1.57079632679 0" xyz="0 0 0" />
    <axis xyz="0 0 1" />
    <limit effort="100.0" lower="-0.785398163397" upper="0.785398163397" velocity="10" />
    <joint_properties damping="1.0" friction="0.0" />
  </joint>
  <link name="wrist_yaw_link">
    <visual>
      <geometry>
        <mesh filename="WristYaw.dae" />
      </geometry>
    </visual>
    <collision>
      <geometry>
        <mesh filename="WristYaw.STL" />
      </geometry>
    </collision>
    <inertial>
      <mass value="0.2" />
      <inertia ixx="0.1" ixy="0.0" ixz="0.0" iyy="0.1" iyz="0.0" izz="0.1" />
    </inertial>
  </link>
  <joint name="wrist_roll_joint" type="revolute">
    <parent link="wrist_yaw_link" />
    <child link="wrist_roll_link" />
    <origin rpy="-1.57079632679 1.57079632679 0" xyz="0 -.039 0" />
    <axis xyz="0 0 -1" />
    <limit effort="100.0" lower="-4.71238898038" upper="4.71238898038" velocity="10" />
    <joint_properties damping="1.0" friction="0.0" />
  </joint>
  <link name="wrist_roll_link">
    <visual>
      <geometry>
        <mesh filename="WristRoll.dae" />
      </geometry>
    </visual>
    <collision>
      <geometry>
        <mesh filename="WristRoll.STL" />
      </geometry>
    </collision>
    <inertial>
      <mass value="0.1" />
      <inertia ixx="0.1" ixy="0.0" ixz="0.0" iyy="0.1" iyz="0.0" izz="0.1" />
    </inertial>
  </link>
  <joint name="base" type="fixed">
    <parent link="top_panel" />
    <child link="base" />
    <origin rpy="0 0 0" xyz="0 0 -0.190" />
  </joint>
  <link name="base" />
  <joint name="end_effector" type="fixed">
    <parent link="wrist_roll_link" />
    <child link="ee_link" />
    <origin rpy="0 3.14159265359 0" xyz="0 0 0.039" />
  </joint>
  <link name="ee_link" />
</robot>